Workbook
Name Categorizacion: [1]Configuracion!$C$2:$C$6
Name CentroServicios: [1]Configuracion!$H$2:$H$4
Name Ciclos_Vida: [1]Configuracion!$D$2:$D$6
Name Eleccion: [1]Configuracion!$F$2:$F$6
Name Eleccion2: [1]Configuracion!$G$2:$G$7
Name Herramienta: [1]Configuracion!$N$2:$N$5
Name Herramienta_P: [1]Configuracion!$L$2:$L$8
Name Herramienta_PE: [1]Configuracion!$M$2:$M$7
Name IS: [1]Configuracion!$O$2:$O$5
Name Prestacion: [1]Configuracion!$B$2:$B$5
Name Requisitos: [1]Configuracion!$K$2:$K$3
Name Tipo_de_servicio: [1]Configuracion!$J$2:$J$5
Name Tipologías: [2]Configuracion!$B$2:$B$6

Sheet Control de Cambios
E5: Clasificación: Documento interno
B7: HISTORIAL DE CAMBIOS
C10: Versión | D10: Descripción | E10: Fecha
C11: 1.0 | D11: Versión inicial | E11: <dd/mm/aaaa>
C14: Nombre | D14: Firma | E14: Fecha
B15: Elaborado por: | C15: <Nombre del Jefe de Proyecto>
B16: Revisado por: | C16: <Nombre del Revisor>
B17: Aprobado por: | C17: <Nombre del miembro del Equipo de Calidad>

Sheet Elementos Base
I3: Elementos de Estimación
B5: Esta pestaña tiene las tablas de estimación (ábacos le llaman en Inetum Francia) que permiten calcular los esfuerzos a partir del tamaño.
C6: Ejemplo Componentes JEE
C8: Ventana | I8: Servicio de Datos | O8: Web Service | U8: Subproceso | AA8: Proceso
C10: Muy baja | D10: Baja | E10: Media | F10: Alta | G10: Muy alta | H10: Especial | I10: Muy baja | J10: Baja | K10: Media | L10: Alta | M10: Muy alta | N10: Especial | O10: Muy baja | P10: Baja | Q10: Media | R10: Alta | S10: Muy alta | T10: Especial | U10: Muy baja | V10: Baja | W10: Media | X10: Alta | Y10: Muy alta | Z10: Especial | AA10: Muy baja | AB10: Baja | AC10: Media | AD10: Alta | AE10: Muy alta | AF10: Especial
C11: MB | D11: B | E11: M | F11: A | G11: MA | H11: E | I11: MB | J11: B | K11: M | L11: A | M11: MA | N11: E | O11: MB | P11: B | Q11: M | R11: A | S11: MA | T11: E | U11: MB | V11: B | W11: M | X11: A | Y11: MA | Z11: E | AA11: MB | AB11: B | AC11: M | AD11: A | AE11: MA | AF11: E
B12: Nuevo | C12: 0.5 | D12: 0.75 | E12: 1.5 | F12: 3 | G12: 5 | I12: =C12+0.5 -> 1 | J12: =D12+0.5 -> 1.25 | K12: =E12+0.5 -> 2 | L12: =F12+0.5 -> 3.5 | M12: =G12+0.5 -> 5.5 | O12: 0.5 | P12: 0.75 | Q12: 1.5 | R12: 3 | S12: 5 | U12: =I12+0.5 -> 1.5 | V12: =J12+0.5 -> 1.75 | W12: =K12+0.5 -> 2.5 | X12: =L12+0.5 -> 4 | Y12: =M12+0.5 -> 6 | AA12: =O12+0.5 -> 1 | AB12: =P12+0.5 -> 1.25 | AC12: =Q12+0.5 -> 2 | AD12: =R12+0.5 -> 3.5 | AE12: =S12+0.5 -> 5.5
B13: Modificación | C13: =C12+0.25 -> 0.75 | D13: =D12+0.25 -> 1 | E13: =E12+0.25 -> 1.75 | F13: =F12+0.25 -> 3.25 | G13: =G12+0.25 -> 5.25 | I13: =C13+0.5 -> 1.25 | J13: =D13+0.5 -> 1.5 | K13: =E13+0.5 -> 2.25 | L13: =F13+0.5 -> 3.75 | M13: =G13+0.5 -> 5.75 | O13: =O12+0.25 -> 0.75 | P13: =P12+0.25 -> 1 | Q13: =Q12+0.25 -> 1.75 | R13: =R12+0.25 -> 3.25 | S13: =S12+0.25 -> 5.25 | U13: =I13+0.5 -> 1.75 | V13: =J13+0.5 -> 2 | W13: =K13+0.5 -> 2.75 | X13: =L13+0.5 -> 4.25 | Y13: =M13+0.5 -> 6.25 | AA13: =O13+0.5 -> 1.25 | AB13: =P13+0.5 -> 1.5 | AC13: =Q13+0.5 -> 2.25 | AD13: =R13+0.5 -> 3.75 | AE13: =S13+0.5 -> 5.75
B14: Nuevo (1) | C14: 0.5 | D14: 0.75 | E14: 1.5 | F14: 3 | G14: 5 | I14: =C14+0.5 -> 1 | J14: =D14+0.5 -> 1.25 | K14: =E14+0.5 -> 2 | L14: =F14+0.5 -> 3.5 | M14: =G14+0.5 -> 5.5 | O14: 0.5 | P14: 0.75 | Q14: 1.5 | R14: 3 | S14: 5 | U14: =I14+0.5 -> 1.5 | V14: =J14+0.5 -> 1.75 | W14: =K14+0.5 -> 2.5 | X14: =L14+0.5 -> 4 | Y14: =M14+0.5 -> 6 | AA14: =O14+0.5 -> 1 | AB14: =P14+0.5 -> 1.25 | AC14: =Q14+0.5 -> 2 | AD14: =R14+0.5 -> 3.5 | AE14: =S14+0.5 -> 5.5
B15: Modificación (2) | C15: =C14+0.25 -> 0.75 | D15: =D14+0.25 -> 1 | E15: =E14+0.25 -> 1.75 | F15: =F14+0.25 -> 3.25 | G15: =G14+0.25 -> 5.25 | I15: =C15+0.5 -> 1.25 | J15: =D15+0.5 -> 1.5 | K15: =E15+0.5 -> 2.25 | L15: =F15+0.5 -> 3.75 | M15: =G15+0.5 -> 5.75 | O15: =O14+0.25 -> 0.75 | P15: =P14+0.25 -> 1 | Q15: =Q14+0.25 -> 1.75 | R15: =R14+0.25 -> 3.25 | S15: =S14+0.25 -> 5.25 | U15: =I15+0.5 -> 1.75 | V15: =J15+0.5 -> 2 | W15: =K15+0.5 -> 2.75 | X15: =L15+0.5 -> 4.25 | Y15: =M15+0.5 -> 6.25 | AA15: =O15+0.5 -> 1.25 | AB15: =P15+0.5 -> 1.5 | AC15: =Q15+0.5 -> 2.25 | AD15: =R15+0.5 -> 3.75 | AE15: =S15+0.5 -> 5.75
B17: (1) y (2) Nota: Las dos líneas de abajo son valores de referencia que utilizamos en Inetum: No se utilizan más que como referencia comparativa, punto de partida.
B18: Los valores a utilizar y que se pueden modificar para esta estimación son las dos primeras líneas.

Sheet Tamaño
E3: Tamaño
F6: Elemento Tipo 1 | L6: Elemento Tipo 2 | R6: Elemento Tipo 3 | X6: Elemento Tipo 4 | AD6: Elemento Tipo 5 | AJ6: Total E | AK6: Total J | AL6: Ajuste Man | AM6: Ajuste Aut | AN6: Comentario útil para la estimación
F7: Ventana | L7: Servicio de Datos | R7: Web Service | X7: Subproceso | AD7: Proceso
E8: Nuevo/Modif | F8: MB | G8: B | H8: M | I8: A | J8: MA | K8: E | L8: MB | M8: B | N8: M | O8: A | P8: MA | Q8: E | R8: MB | S8: B | T8: M | U8: A | V8: MA | W8: E | X8: MB | Y8: B | Z8: M | AA8: A | AB8: MA | AC8: E | AD8: MB | AE8: B | AF8: M | AG8: A | AH8: MA | AI8: E
E9: Nº Nuevos | F9: =SUMIF($E$15:$E$1048576,$E9,F$15:F$1048576) -> 0 | G9: =SUMIF($E$15:$E$1048576,$E9,G$15:G$1048576) -> 0 | H9: =SUMIF($E$15:$E$1048576,$E9,H$15:H$1048576) -> 0 | I9: =SUMIF($E$15:$E$1048576,$E9,I$15:I$1048576) -> 0 | J9: =SUMIF($E$15:$E$1048576,$E9,J$15:J$1048576) -> 0 | K9: =SUMIF($E$15:$E$1048576,$E9,K$15:K$1048576) -> 0 | L9: =SUMIF($E$15:$E$1048576,$E9,L$15:L$1048576) -> 0 | M9: =SUMIF($E$15:$E$1048576,$E9,M$15:M$1048576) -> 0 | ... AI9: =SUMIF($E$15:$E$1048576,$E9,AI$15:AI$1048576) -> 0 | AJ9: =SUM(F9:AI9) -> 0
E10: Nº Modif | F10: =SUMIF($E$15:$E$1048576,$E10,F$15:F$1048576) -> 0 | G10: =SUMIF($E$15:$E$1048576,$E10,G$15:G$1048576) -> 0 | H10: =SUMIF($E$15:$E$1048576,$E10,H$15:H$1048576) -> 0 | I10: =SUMIF($E$15:$E$1048576,$E10,I$15:I$1048576) -> 0 | J10: =SUMIF($E$15:$E$1048576,$E10,J$15:J$1048576) -> 0 | K10: =SUMIF($E$15:$E$1048576,$E10,K$15:K$1048576) -> 0 | L10: =SUMIF($E$15:$E$1048576,$E10,L$15:L$1048576) -> 0 | M10: =SUMIF($E$15:$E$1048576,$E10,M$15:M$1048576) -> 0 | ... AI10: =SUMIF($E$15:$E$1048576,$E10,AI$15:AI$1048576) -> 0 | AJ10: =SUM(F10:AI10) -> 0
E11: J. Nuevos | F11: =SUMIF($E$15:$E$1048576,$E11,F$15:F$1048576) -> 0 | G11: =SUMIF($E$15:$E$1048576,$E11,G$15:G$1048576) -> 0 | H11: =SUMIF($E$15:$E$1048576,$E11,H$15:H$1048576) -> 0 | I11: =SUMIF($E$15:$E$1048576,$E11,I$15:I$1048576) -> 0 | J11: =SUMIF($E$15:$E$1048576,$E11,J$15:J$1048576) -> 0 | K11: =SUMIF($E$15:$E$1048576,$E11,K$15:K$1048576) -> 0 | L11: =SUMIF($E$15:$E$1048576,$E11,L$15:L$1048576) -> 0 | M11: =SUMIF($E$15:$E$1048576,$E11,M$15:M$1048576) -> 0 | ... AI11: =SUMIF($E$15:$E$1048576,$E11,AI$15:AI$1048576) -> 0 | AK11: =SUM(F11:AI11) -> 0 | AL11: =SUMIF($E$15:$E$1048576,$E11,AL$15:AL$1048576) -> 0 | AM11: =AL11*Ajustes!$H$25 -> 0
E12: J. Modif | F12: =SUMIF($E$15:$E$1048576,$E12,F$15:F$1048576) -> 0 | G12: =SUMIF($E$15:$E$1048576,$E12,G$15:G$1048576) -> 0 | H12: =SUMIF($E$15:$E$1048576,$E12,H$15:H$1048576) -> 0 | I12: =SUMIF($E$15:$E$1048576,$E12,I$15:I$1048576) -> 0 | J12: =SUMIF($E$15:$E$1048576,$E12,J$15:J$1048576) -> 0 | K12: =SUMIF($E$15:$E$1048576,$E12,K$15:K$1048576) -> 0 | L12: =SUMIF($E$15:$E$1048576,$E12,L$15:L$1048576) -> 0 | M12: =SUMIF($E$15:$E$1048576,$E12,M$15:M$1048576) -> 0 | ... AI12: =SUMIF($E$15:$E$1048576,$E12,AI$15:AI$1048576) -> 0 | AK12: =SUM(F12:AI12) -> 0 | AL12: =SUMIF($E$15:$E$1048576,$E12,AL$15:AL$1048576) -> 0 | AM12: =AL12*Ajustes!$H$25 -> 0
AJ13: =SUM(AJ9:AJ12) -> 0 | AK13: =SUM(AK9:AK12) -> 0 | AL13: =SUM(AL9:AL12) -> 0 | AM13: =SUM(AM9:AM12) -> 0
F15: Elemento Tipo 1 | L15: Elemento Tipo 2 | R15: Elemento Tipo 3 | X15: Elemento Tipo 4 | AD15: Elemento Tipo 5 | AJ15: Total E | AK15: Total J | AL15: Ajuste Man | AM15: Ajuste Aut | AN15: Comentario útil para la estimación
F16: Ventana | L16: Servicio de Datos | R16: Web Service | X16: Subproceso | AD16: Proceso
B17: Subsistema | C17: Módulo | D17: Funcionalidad | E17: Nuevo/Modif | F17: MB | G17: B | H17: M | I17: A | J17: MA | K17: E | L17: MB | M17: B | N17: M | O17: A | P17: MA | Q17: E | R17: MB | S17: B | T17: M | U17: A | V17: MA | W17: E | X17: MB | Y17: B | Z17: M | AA17: A | AB17: MA | AC17: E | AD17: MB | AE17: B | AF17: M | AG17: A | AH17: MA | AI17: E
E18: Nº Nuevos | AJ18: =SUM(F18:AI18) -> 0
E19: Nº Modif | AJ19: =SUM(F19:AI19) -> 0
E20: J. Nuevos | F20: =IF(F18="","",F18*'Elementos Base'!C$12) | G20: =IF(G18="","",G18*'Elementos Base'!D$12) | H20: =IF(H18="","",H18*'Elementos Base'!E$12) | I20: =IF(I18="","",I18*'Elementos Base'!F$12) | J20: =IF(J18="","",J18*'Elementos Base'!G$12) | K20: =IF(K18="","",K18*'Elementos Base'!H$12) | L20: =IF(L18="","",L18*'Elementos Base'!I$12) | M20: =IF(M18="","",M18*'Elementos Base'!J$12) | ... AI20: =IF(AI18="","",AI18*'Elementos Base'!AF$12) | AK20: =SUM(F20:AI20) -> 0 | AL20: =AK20 -> 0 | AM20: =AL20*Ajustes!$H$25 -> 0
E21: J. Modif | F21: =IF(F19="","",F19*'Elementos Base'!C$13) | G21: =IF(G19="","",G19*'Elementos Base'!D$13) | H21: =IF(H19="","",H19*'Elementos Base'!E$13) | I21: =IF(I19="","",I19*'Elementos Base'!F$13) | J21: =IF(J19="","",J19*'Elementos Base'!G$13) | K21: =IF(K19="","",K19*'Elementos Base'!H$13) | L21: =IF(L19="","",L19*'Elementos Base'!I$13) | M21: =IF(M19="","",M19*'Elementos Base'!J$13) | ... AI21: =IF(AI19="","",AI19*'Elementos Base'!AF$13) | AK21: =SUM(F21:AI21) -> 0 | AL21: =AK21 -> 0 | AM21: =AL21*Ajustes!$H$25 -> 0
E22: Nº Nuevos | AJ22: =SUM(F22:AI22) -> 0
E23: Nº Modif | AJ23: =SUM(F23:AI23) -> 0
E24: J. Nuevos | F24: =IF(F22="","",F22*'Elementos Base'!C$12) | G24: =IF(G22="","",G22*'Elementos Base'!D$12) | H24: =IF(H22="","",H22*'Elementos Base'!E$12) | I24: =IF(I22="","",I22*'Elementos Base'!F$12) | J24: =IF(J22="","",J22*'Elementos Base'!G$12) | K24: =IF(K22="","",K22*'Elementos Base'!H$12) | L24: =IF(L22="","",L22*'Elementos Base'!I$12) | M24: =IF(M22="","",M22*'Elementos Base'!J$12) | ... AI24: =IF(AI22="","",AI22*'Elementos Base'!AF$12) | AK24: =SUM(F24:AI24) -> 0 | AL24: =AK24 -> 0 | AM24: =AL24*Ajustes!$H$25 -> 0
E25: J. Modif | F25: =IF(F23="","",F23*'Elementos Base'!C$13) | G25: =IF(G23="","",G23*'Elementos Base'!D$13) | H25: =IF(H23="","",H23*'Elementos Base'!E$13) | I25: =IF(I23="","",I23*'Elementos Base'!F$13) | J25: =IF(J23="","",J23*'Elementos Base'!G$13) | K25: =IF(K23="","",K23*'Elementos Base'!H$13) | L25: =IF(L23="","",L23*'Elementos Base'!I$13) | M25: =IF(M23="","",M23*'Elementos Base'!J$13) | ... AI25: =IF(AI23="","",AI23*'Elementos Base'!AF$13) | AK25: =SUM(F25:AI25) -> 0 | AL25: =AK25 -> 0 | AM25: =AL25*Ajustes!$H$25 -> 0
E26: Nº Nuevos | AJ26: =SUM(F26:AI26) -> 0
E27: Nº Modif | AJ27: =SUM(F27:AI27) -> 0
E28: J. Nuevos | F28: =IF(F26="","",F26*'Elementos Base'!C$12) | G28: =IF(G26="","",G26*'Elementos Base'!D$12) | H28: =IF(H26="","",H26*'Elementos Base'!E$12) | I28: =IF(I26="","",I26*'Elementos Base'!F$12) | J28: =IF(J26="","",J26*'Elementos Base'!G$12) | K28: =IF(K26="","",K26*'Elementos Base'!H$12) | L28: =IF(L26="","",L26*'Elementos Base'!I$12) | M28: =IF(M26="","",M26*'Elementos Base'!J$12) | ... AI28: =IF(AI26="","",AI26*'Elementos Base'!AF$12) | AK28: =SUM(F28:AI28) -> 0 | AL28: =AK28 -> 0 | AM28: =AL28*Ajustes!$H$25 -> 0
E29: J. Modif | F29: =IF(F27="","",F27*'Elementos Base'!C$13) | G29: =IF(G27="","",G27*'Elementos Base'!D$13) | H29: =IF(H27="","",H27*'Elementos Base'!E$13) | I29: =IF(I27="","",I27*'Elementos Base'!F$13) | J29: =IF(J27="","",J27*'Elementos Base'!G$13) | K29: =IF(K27="","",K27*'Elementos Base'!H$13) | L29: =IF(L27="","",L27*'Elementos Base'!I$13) | M29: =IF(M27="","",M27*'Elementos Base'!J$13) | ... AI29: =IF(AI27="","",AI27*'Elementos Base'!AF$13) | AK29: =SUM(F29:AI29) -> 0 | AL29: =AK29 -> 0 | AM29: =AL29*Ajustes!$H$25 -> 0
E30: Nº Nuevos | AJ30: =SUM(F30:AI30) -> 0
E31: Nº Modif | AJ31: =SUM(F31:AI31) -> 0
E32: J. Nuevos | F32: =IF(F30="","",F30*'Elementos Base'!C$12) | G32: =IF(G30="","",G30*'Elementos Base'!D$12) | H32: =IF(H30="","",H30*'Elementos Base'!E$12) | I32: =IF(I30="","",I30*'Elementos Base'!F$12) | J32: =IF(J30="","",J30*'Elementos Base'!G$12) | K32: =IF(K30="","",K30*'Elementos Base'!H$12) | L32: =IF(L30="","",L30*'Elementos Base'!I$12) | M32: =IF(M30="","",M30*'Elementos Base'!J$12) | ... AI32: =IF(AI30="","",AI30*'Elementos Base'!AF$12) | AK32: =SUM(F32:AI32) -> 0 | AL32: =AK32 -> 0 | AM32: =AL32*Ajustes!$H$25 -> 0
E33: J. Modif | F33: =IF(F31="","",F31*'Elementos Base'!C$13) | G33: =IF(G31="","",G31*'Elementos Base'!D$13) | H33: =IF(H31="","",H31*'Elementos Base'!E$13) | I33: =IF(I31="","",I31*'Elementos Base'!F$13) | J33: =IF(J31="","",J31*'Elementos Base'!G$13) | K33: =IF(K31="","",K31*'Elementos Base'!H$13) | L33: =IF(L31="","",L31*'Elementos Base'!I$13) | M33: =IF(M31="","",M31*'Elementos Base'!J$13) | ... AI33: =IF(AI31="","",AI31*'Elementos Base'!AF$13) | AK33: =SUM(F33:AI33) -> 0 | AL33: =AK33 -> 0 | AM33: =AL33*Ajustes!$H$25 -> 0
E34: Nº Nuevos | AJ34: =SUM(F34:AI34) -> 0
E35: Nº Modif | AJ35: =SUM(F35:AI35) -> 0
E36: J. Nuevos | F36: =IF(F34="","",F34*'Elementos Base'!C$12) | G36: =IF(G34="","",G34*'Elementos Base'!D$12) | H36: =IF(H34="","",H34*'Elementos Base'!E$12) | I36: =IF(I34="","",I34*'Elementos Base'!F$12) | J36: =IF(J34="","",J34*'Elementos Base'!G$12) | K36: =IF(K34="","",K34*'Elementos Base'!H$12) | L36: =IF(L34="","",L34*'Elementos Base'!I$12) | M36: =IF(M34="","",M34*'Elementos Base'!J$12) | ... AI36: =IF(AI34="","",AI34*'Elementos Base'!AF$12) | AK36: =SUM(F36:AI36) -> 0 | AL36: =AK36 -> 0 | AM36: =AL36*Ajustes!$H$25 -> 0
E37: J. Modif | F37: =IF(F35="","",F35*'Elementos Base'!C$13) | G37: =IF(G35="","",G35*'Elementos Base'!D$13) | H37: =IF(H35="","",H35*'Elementos Base'!E$13) | I37: =IF(I35="","",I35*'Elementos Base'!F$13) | J37: =IF(J35="","",J35*'Elementos Base'!G$13) | K37: =IF(K35="","",K35*'Elementos Base'!H$13) | L37: =IF(L35="","",L35*'Elementos Base'!I$13) | M37: =IF(M35="","",M35*'Elementos Base'!J$13) | ... AI37: =IF(AI35="","",AI35*'Elementos Base'!AF$13) | AK37: =SUM(F37:AI37) -> 0 | AL37: =AK37 -> 0 | AM37: =AL37*Ajustes!$H$25 -> 0
E38: Nº Nuevos | AJ38: =SUM(F38:AI38) -> 0
E39: Nº Modif | AJ39: =SUM(F39:AI39) -> 0
E40: J. Nuevos | F40: =IF(F38="","",F38*'Elementos Base'!C$12) | G40: =IF(G38="","",G38*'Elementos Base'!D$12) | H40: =IF(H38="","",H38*'Elementos Base'!E$12) | I40: =IF(I38="","",I38*'Elementos Base'!F$12) | J40: =IF(J38="","",J38*'Elementos Base'!G$12) | K40: =IF(K38="","",K38*'Elementos Base'!H$12) | L40: =IF(L38="","",L38*'Elementos Base'!I$12) | M40: =IF(M38="","",M38*'Elementos Base'!J$12) | ... AI40: =IF(AI38="","",AI38*'Elementos Base'!AF$12) | AK40: =SUM(F40:AI40) -> 0 | AL40: =AK40 -> 0 | AM40: =AL40*Ajustes!$H$25 -> 0
E41: J. Modif | F41: =IF(F39="","",F39*'Elementos Base'!C$13) | G41: =IF(G39="","",G39*'Elementos Base'!D$13) | H41: =IF(H39="","",H39*'Elementos Base'!E$13) | I41: =IF(I39="","",I39*'Elementos Base'!F$13) | J41: =IF(J39="","",J39*'Elementos Base'!G$13) | K41: =IF(K39="","",K39*'Elementos Base'!H$13) | L41: =IF(L39="","",L39*'Elementos Base'!I$13) | M41: =IF(M39="","",M39*'Elementos Base'!J$13) | ... AI41: =IF(AI39="","",AI39*'Elementos Base'!AF$13) | AK41: =SUM(F41:AI41) -> 0 | AL41: =AK41 -> 0 | AM41: =AL41*Ajustes!$H$25 -> 0
E42: Nº Nuevos | AJ42: =SUM(F42:AI42) -> 0
E43: Nº Modif | AJ43: =SUM(F43:AI43) -> 0
E44: J. Nuevos | F44: =IF(F42="","",F42*'Elementos Base'!C$12) | G44: =IF(G42="","",G42*'Elementos Base'!D$12) | H44: =IF(H42="","",H42*'Elementos Base'!E$12) | I44: =IF(I42="","",I42*'Elementos Base'!F$12) | J44: =IF(J42="","",J42*'Elementos Base'!G$12) | K44: =IF(K42="","",K42*'Elementos Base'!H$12) | L44: =IF(L42="","",L42*'Elementos Base'!I$12) | M44: =IF(M42="","",M42*'Elementos Base'!J$12) | ... AI44: =IF(AI42="","",AI42*'Elementos Base'!AF$12) | AK44: =SUM(F44:AI44) -> 0 | AL44: =AK44 -> 0 | AM44: =AL44*Ajustes!$H$25 -> 0
E45: J. Modif | F45: =IF(F43="","",F43*'Elementos Base'!C$13) | G45: =IF(G43="","",G43*'Elementos Base'!D$13) | H45: =IF(H43="","",H43*'Elementos Base'!E$13) | I45: =IF(I43="","",I43*'Elementos Base'!F$13) | J45: =IF(J43="","",J43*'Elementos Base'!G$13) | K45: =IF(K43="","",K43*'Elementos Base'!H$13) | L45: =IF(L43="","",L43*'Elementos Base'!I$13) | M45: =IF(M43="","",M43*'Elementos Base'!J$13) | ... AI45: =IF(AI43="","",AI43*'Elementos Base'!AF$13) | AK45: =SUM(F45:AI45) -> 0 | AL45: =AK45 -> 0 | AM45: =AL45*Ajustes!$H$25 -> 0
...

Sheet Ajustes
C3: Factores de Ajuste
B6: Factor Ajuste (1) | C6: Descripción | D6: Valoraciones | E6: Valores | F6: Valor estimado | G6: Valor ajuste referencia | H6: Valor ajuste manual
B7: Equipo participante en el Proyecto | C7: Conocimientos,experiencia y capacidades de los miembros previstos del equipo para este proyecto, a cada nivel (negocio-funcional, arquitectura-desarrollo, cliente-entorno, tecnologías-lenguajes-plataformas) | D7: Muy bajo | E7: 1.47 | F7: Estándar | G7: =VLOOKUP(F7,D7:E11,2,FALSE) -> 1 | H7: =G7 -> 1
D8: Bajo | E8: =(E7+E9)/2 -> 1.235
D9: Estándar | E9: 1
D10: Alto | E10: =(E9+E11)/2 -> 0.835
D11: Muy alto | E11: 0.67
B12: Madurez del proceso de desarrollo software a utilizar | C12: Metodología de trabajo clara y predefinida, fases y entregables concretos, herramientas disponibles adecuadas y suficientes | D12: Muy bajo | E12: =109%*109% -> 1.1881 | F12: Estándar | G12: =VLOOKUP(F12,D12:E14,2,FALSE) -> 1 | H12: =G12 -> 1
D13: Bajo | E13: =(E12+E14)/2 -> 1.09405
D14: Estándar | E14: 1
B15: Características del Proyecto | C15: Plazos del proyecto (si se imponen o hay un requisito) | D15: Estándar | E15: 1 | F15: Estándar | G15: =VLOOKUP(F15,D15:E17,2,FALSE) -> 1 | H15: =G15 -> 1 | I15: Raiz cuadrada de meses*hombre = plazo
D16: Ajustados | E16: 1.08 | I16: Plazo= 0,9 * Raiz cuadrada de meses*hombre
D17: Muy ajustados | E17: 1.23 | I17: Plazo= 0,8 * Raiz cuadrada de meses*hombre
C18: Proyecto ejecutado en Factoría (nearshore, Alicante) | D18: No | E18: 1 | F18: No | G18: =VLOOKUP(F18,D18:E19,2,FALSE) -> 1 | H18: =G18 -> 1
D19: Si (backoffice) | E19: =1+9% -> 1.09
B20: Otros ajustes (explicar) | C20: Ajuste relativo al margen teórico | D20: Alto | E20: 1.5 | F20: Medio | G20: =VLOOKUP(F20,D20:E24,2,FALSE) -> 1.15 | H20: =G20 -> 1.15
D21: Medio | E21: 1.15
D22: Bajo | E22: 1.1
D23: Muy bajo | E23: 1.05
D24: Sin margen | E24: 1
C25: VALOR FINAL DE AJUSTE | G25: =G7*G12*G15*G18*G20 -> 1.15 | H25: =H7*H12*H15*H18*H20 -> 1.15
B26: (1) Notas:
B27: * Los factores de ajuste ponderan la estimación de esfuerzos en función de las diferencias entre las condiciones de un proyecto considerado estándar y las condiciones concretas de este proyecto
B28: * Usar ajustes generales permite mantener la medida de tamaño y las tablas de estimación estándar y lo más generales posibles, de manera que los factores de ajuste se valoren aparte por separado.
B29: * Se distinguen del riesgo A, B, C, D que determina la provisión por riesgo porque ajustan el volumen de jornadas que se otorgan al JP para ejecutar el proyecto (ver la pestaña siguiente y la hoja de márgenes)
B30: * Los factores de ajuste se determinan en base a hechos o asunciones fiables, no a riesgos que pueden o no producirse.
B31: * Es importante no introducir factores de corrección dos veces en el proceso de estimación. Si se han introducido ya en la medida de tamaño o complejidad, no se deben meter de nuevo aquí.
B32: * Los ajustes intrínsecos al software a construir (producto) no se consideran aquí, están en tamaño y complejidad. Los intrínsecos al proyecto o los extrínsecos (ambientales) sí que están aquí.

Sheet Etapas
C3: Etapas
B6: Las etapas de división del proyecto deben estar alineadas con la descomposición del trabajo (WBS)
C8: Canónico
C9: % total | D9: % sobre Construcción | E9: Jornadas
B10: Planificación y Seguimiento | C10: 0.08 | D10: =C10/C$13 -> 0.32 | E10: =E$13*D10 -> 0
B11: Análisis de Requisitos | C11: 0.12 | D11: =C11/C$13 -> 0.48 | E11: =E$13*D11 -> 0
B12: Diseño funcional y técnico | C12: 0.14 | D12: =C12/C$13 -> 0.56 | E12: =E$13*D12 -> 0
B13: Construcción y pruebas unitarias | C13: 0.25 | D13: =C13/C$13 -> 1 | E13: =Tamaño!AM13 -> 0
B14: Pruebas de sistema | C14: 0.16 | D14: =C14/C$13 -> 0.64 | E14: =E$13*D14 -> 0
B15: Aseguramiento de calidad | C15: 0.05 | D15: =C15/C$13 -> 0.2 | E15: =E$13*D15 -> 0
B16: Documentación | C16: 0.05 | D16: =C16/C$13 -> 0.2 | E16: =E$13*D16 -> 0
B17: UAT | C17: 0.05 | D17: =C17/C$13 -> 0.2 | E17: =E$13*D17 -> 0
B18: Cierre | C18: 0.05 | D18: =C18/C$13 -> 0.2 | E18: =E$13*D18 -> 0
B19: Garantía | C19: 0.05 | D19: =C19/C$13 -> 0.2 | E19: =E$13*D19 -> 0
B20: Totales | C20: =SUM(C10:C19) -> 1 | D20: =SUM(D10:D19) -> 4 | E20: =SUM(E10:E19) -> 0
C23: Ajuste Manual
C24: % total | D24: % sobre Construcción | E24: Jornadas
B25: Planificación y Seguimiento | C25: 0.04 | D25: =$C25/$C$28 -> 0.16 | E25: =E$28*D25 -> 0
B26: Análisis de Requisitos | C26: 0.04 | D26: =$C26/$C$28 -> 0.16 | E26: =E$28*D26 -> 0
B27: Diseño funcional y técnico | C27: 0.1 | D27: =$C27/$C$28 -> 0.4 | E27: =E$28*D27 -> 0
B28: Construcción y pruebas unitarias | C28: 0.25 | D28: =$C28/$C$28 -> 1 | E28: =E13 -> 0
B29: Pruebas de sistema | C29: 0 | D29: =$C29/$C$28 -> 0 | E29: =E$28*D29 -> 0
B30: Aseguramiento de calidad | C30: 0 | D30: =$C30/$C$28 -> 0 | E30: =E$28*D30 -> 0
B31: Documentación | C31: 0 | D31: =$C31/$C$28 -> 0 | E31: =E$28*D31 -> 0
B32: UAT | C32: 0.05 | D32: =$C32/$C$28 -> 0.2 | E32: =E$28*D32 -> 0
B33: Cierre | C33: 0 | D33: =$C33/$C$28 -> 0 | E33: =E$28*D33 -> 0
B34: Garantía | C34: 0.05 | D34: =$C34/$C$28 -> 0.2 | E34: =E$28*D34 -> 0
B35: Totales | C35: =SUM(C25:C34) -> 0.53 | D35: =SUM(D25:D34) -> 2.12 | E35: =SUM(E25:E34) -> 0
B38: Estimación DKV (en horas)
B39: Sin Diseño Funcional | C39: =ROUND(SUM($E$25,$E$26,$E$28:$E$34)*8,0) -> 0
B40: Con Diseño Funcional | C40: =ROUND(E35*8,0) -> 0

Sheet Recursos
D3: Recursos
B7: % Dedicación perfiles por etapa WBS | C7: Planificación y Seguimiento | D7: Análisis de Requisitos | E7: Diseño funcional y técnico | F7: Construcción y pruebas unitarias | G7: Pruebas de sistema | H7: Aseguramiento de calidad | I7: Documentación | J7: UAT | K7: Cierre | L7: Garantía
B8: Jefe de Proyecto | C8: 0.8 | D8: 0.1 | E8: 0 | F8: 0 | G8: 0 | H8: 0 | I8: 0.1 | J8: 0.2 | K8: 0.8 | L8: 0
B9: Jefe de Equipo | C9: 0.2 | D9: 0.1 | E9: 0.1 | F9: 0 | G9: 0 | H9: 0 | I9: 0.1 | J9: 0.2 | K9: 0.2 | L9: 0
B10: Analista Funcional | C10: 0 | D10: 0.5 | E10: 0.3 | F10: 0.1 | G10: 0 | H10: 0 | I10: 0.6 | J10: 0.2 | K10: 0 | L10: 0
B11: Ingeniero Desarrollo | C11: 0 | D11: 0.2 | E11: 0.4 | F11: 0.2 | G11: 0 | H11: 0 | I11: 0.2 | J11: 0 | K11: 0 | L11: 0
B12: Analista Programador | C12: 0 | D12: 0.1 | E12: 0.2 | F12: 0.2 | G12: 0 | H12: 0 | I12: 0 | J12: 0 | K12: 0 | L12: 0.5
B13: Analista de Pruebas | C13: 0 | D13: 0 | E13: 0 | F13: 0 | G13: 0.3 | H13: 0 | I13: 0 | J13: 0.4 | K13: 0 | L13: 0
B14: Ingeniero de Pruebas | C14: 0 | D14: 0 | E14: 0 | F14: 0 | G14: 0.7 | H14: 0 | I14: 0 | J14: 0 | K14: 0 | L14: 0
B15: Programador | C15: 0 | D15: 0 | E15: 0 | F15: 0.5 | G15: 0 | H15: 0 | I15: 0 | J15: 0 | K15: 0 | L15: 0.5
B16: Responsable de Calidad | C16: 0 | D16: 0 | E16: 0 | F16: 0 | G16: 0 | H16: 1 | I16: 0 | J16: 0 | K16: 0 | L16: 0
B17: TOTAL | C17: =SUM(C8:C16) -> 1 | D17: =SUM(D8:D16) -> 1 | E17: =SUM(E8:E16) -> 1 | F17: =SUM(F8:F16) -> 1 | G17: =SUM(G8:G16) -> 1 | H17: =SUM(H8:H16) -> 1 | I17: =SUM(I8:I16) -> 1 | J17: =SUM(J8:J16) -> 1 | ... L17: =SUM(L8:L16) -> 1
B20: Distribución jornadas por perfil | C20: Planificación y Seguimiento | D20: Análisis de Requisitos | E20: Diseño funcional y técnico | F20: Construcción y pruebas unitarias | G20: Pruebas de sistema | H20: Aseguramiento de calidad | I20: Documentación | J20: UAT | K20: Cierre | L20: Garantía | M20: TOTAL
B21: Jornadas | C21: =Etapas!E25 -> 0 | D21: =Etapas!E26 -> 0 | E21: =Etapas!E27 -> 0 | F21: =Etapas!E28 -> 0 | G21: =Etapas!E29 -> 0 | H21: =Etapas!E30 -> 0 | I21: =Etapas!E31 -> 0 | J21: =Etapas!E32 -> 0 | K21: =Etapas!E33 -> 0 | L21: =Etapas!E34 -> 0 | M21: =SUM(C21:L21) -> 0
B22: Jefe de Proyecto | C22: =C$21*C8 -> 0 | D22: =D$21*D8 -> 0 | E22: =E$21*E8 -> 0 | F22: =F$21*F8 -> 0 | G22: =G$21*G8 -> 0 | H22: =H$21*H8 -> 0 | I22: =I$21*I8 -> 0 | J22: =J$21*J8 -> 0 | ... L22: =L$21*L8 -> 0 | M22: =SUM(C22:L22) -> 0
B23: Jefe de Equipo | C23: =C$21*C9 -> 0 | D23: =D$21*D9 -> 0 | E23: =E$21*E9 -> 0 | F23: =F$21*F9 -> 0 | G23: =G$21*G9 -> 0 | H23: =H$21*H9 -> 0 | I23: =I$21*I9 -> 0 | J23: =J$21*J9 -> 0 | ... L23: =L$21*L9 -> 0 | M23: =SUM(C23:L23) -> 0
B24: Analista Funcional | C24: =C$21*C10 -> 0 | D24: =D$21*D10 -> 0 | E24: =E$21*E10 -> 0 | F24: =F$21*F10 -> 0 | G24: =G$21*G10 -> 0 | H24: =H$21*H10 -> 0 | I24: =I$21*I10 -> 0 | J24: =J$21*J10 -> 0 | ... L24: =L$21*L10 -> 0 | M24: =SUM(C24:L24) -> 0
B25: Ingeniero Desarrollo | C25: =C$21*C11 -> 0 | D25: =D$21*D11 -> 0 | E25: =E$21*E11 -> 0 | F25: =F$21*F11 -> 0 | G25: =G$21*G11 -> 0 | H25: =H$21*H11 -> 0 | I25: =I$21*I11 -> 0 | J25: =J$21*J11 -> 0 | ... L25: =L$21*L11 -> 0 | M25: =SUM(C25:L25) -> 0
B26: Analista Programador | C26: =C$21*C12 -> 0 | D26: =D$21*D12 -> 0 | E26: =E$21*E12 -> 0 | F26: =F$21*F12 -> 0 | G26: =G$21*G12 -> 0 | H26: =H$21*H12 -> 0 | I26: =I$21*I12 -> 0 | J26: =J$21*J12 -> 0 | ... L26: =L$21*L12 -> 0 | M26: =SUM(C26:L26) -> 0
B27: Analista de Pruebas | C27: =C$21*C13 -> 0 | D27: =D$21*D13 -> 0 | E27: =E$21*E13 -> 0 | F27: =F$21*F13 -> 0 | G27: =G$21*G13 -> 0 | H27: =H$21*H13 -> 0 | I27: =I$21*I13 -> 0 | J27: =J$21*J13 -> 0 | ... L27: =L$21*L13 -> 0 | M27: =SUM(C27:L27) -> 0
B28: Ingeniero de Pruebas | C28: =C$21*C14 -> 0 | D28: =D$21*D14 -> 0 | E28: =E$21*E14 -> 0 | F28: =F$21*F14 -> 0 | G28: =G$21*G14 -> 0 | H28: =H$21*H14 -> 0 | I28: =I$21*I14 -> 0 | J28: =J$21*J14 -> 0 | ... L28: =L$21*L14 -> 0 | M28: =SUM(C28:L28) -> 0
B29: Programador | C29: =C$21*C15 -> 0 | D29: =D$21*D15 -> 0 | E29: =E$21*E15 -> 0 | F29: =F$21*F15 -> 0 | G29: =G$21*G15 -> 0 | H29: =H$21*H15 -> 0 | I29: =I$21*I15 -> 0 | J29: =J$21*J15 -> 0 | ... L29: =L$21*L15 -> 0 | M29: =SUM(C29:L29) -> 0
B30: Responsable de Calidad | C30: =C$21*C16 -> 0 | D30: =D$21*D16 -> 0 | E30: =E$21*E16 -> 0 | F30: =F$21*F16 -> 0 | G30: =G$21*G16 -> 0 | H30: =H$21*H16 -> 0 | I30: =I$21*I16 -> 0 | J30: =J$21*J16 -> 0 | ... L30: =L$21*L16 -> 0 | M30: =SUM(C30:L30) -> 0
B31: TOTAL | C31: =SUM(C22:C30) -> 0 | D31: =SUM(D22:D30) -> 0 | E31: =SUM(E22:E30) -> 0 | F31: =SUM(F22:F30) -> 0 | G31: =SUM(G22:G30) -> 0 | H31: =SUM(H22:H30) -> 0 | I31: =SUM(I22:I30) -> 0 | J31: =SUM(J22:J30) -> 0 | ... M31: =SUM(M22:M30) -> 0

Sheet Estimación
C3: Resumen de la Estimación
B7: Jornadas estimadas para el proyecto | C7: Jornadas internas estimadas para el proyecto | D7: =ROUND(Etapas!E35,0) -> 0
B8: Código Petición Jira | C8: Código de la issue de Jira
B9: Autores estimación | C9: Nombres de las personas que han hecho la estimación
B10: Revisión estimación | C10: Nombres de las personas que han revisado la estimación
B11: Fecha y fase de la estimación | C11: Fecha en que se hizo la estimación y si fue en fase de oferta, requisitos, análisis, diseño, construcción, pruebas.
B12: Requisitos/Información de partida | C12: Descripción de qué información se utilizó de partida (fecha o versión de los requisitos, RFP y otros documentos) | D12: Información extraída del Jira.
B13: Descripción del proyecto | C13: Comentarios de utilidad para la estimación: asunciones, supuestos, contexto, condicionantes, factores de presión, toda la info importante para el que reciba la estimación no habiendo participado en ella.
B14: Proyectos similares considerados | C14: Nombre/cliente de varios proyectos que se consideran más similares a este (en tipología, tecnología, complejidad, tamaño, etc). Cuyas estimaciones sirven para comparar.
B15: Bondad de la estimación | C15: Muy baja- La estimación es una primerísima aproximación de orden de magnitud Baja-La estimación tiene muchos supuestos, parte de información inicial del proyecto Media-La estimación parte de buena información cualitativa y cuantitativa Alta-La estimación parte de mucha información y conocimiento
B16: Riesgos | C16: Descripción de los mayores riesgos que se identifican a la luz del trabajo realizado para estimar., por ejemplo: * El alcance del módulo X, Y, Z está definido de manera muy vaga, y se ha supuesto A, B, C en esos aspectos * Se ha pensado que se va a contar con soporte de R, S, T, en la ejecución * Se considera que el cliente coordinará con Q, W, E el proyecto ...
B18: * Es una medida de la probabilidad de que el proyecto se tuerza y haya desviaciones en contra de Inetum. Se usa para realizar una provisión de jornadas a nivel Gerente (Dirección del Proyecto). Se gestiona siempre por encima del JP.
B19: * Se trata por tanto de hacer una estimación lo más ajustada posible (para vender, y para medir el delivery en base a estándares), pero calibrar aparte qué posibilidad hay de que nos hayamos quedado cortos.
B20: * Los criterios a evaluar para fijar el riesgo del proyecto son los 3 siguientes:
B21: Cliente | C21: Conocimiento y control que tenemos del cliente, en función de la relación existente Inetum-CLIENTE.
B22: Tecnología | C22: Grado de conocimiento que hay en todo Inetum de las tecnologías a utilizar.
C23: Medida de la posibilidad de que aparezcan problemas técnicos y tardemos más de la cuenta en resolverlos.
C24: No confundir con el conocimiento concreto del equipo participante, que es un ajuste, no un riesgo.
B25: Alcance | C25: Posibilidad de que el alcance esté mal, varíe, nos sorprenda, etc. Cuantos más supuestos hemos tenido que hacer sobre el alcance (y asunciones), mayor riesgo.

Sheet Ayuda
B7: Versión plantilla | C7: Autores | D7: Fecha
B8: 0.7 | C8: Javier Rivas, Mariano Vélez, Ubaldo Serna, Equipo CMMI | D8: 41654
B9: 1.0 | C9: Eduardo Riol | D9: 42353
B10: 2.0 | C10: Carlos Honrubia | D10: 43686
B11: 3.0 | C11: Joaquín Cervera | D11: 44651
B12: 4.0 | C12: Adaptación Servicio AMS.NET (DKV) | D12: 45187
B16: Descripción general del uso de la plantilla
B17: Rellenar sólo las celdas en verde
B18: Comenzar descomponiendo el software a realizar en la pestaña Tamaño
B19: Categorizar los desarrollos a hacer en tipologías de elementos base
B20: Identificar las métricas de tamaño por tipo de elemento, incluyendo el tamaño de los cambios o imprevistos que pueden llegar (etiquetarlos bien para diferenciarlos)
B21: Ajustar según factores independientes del tamaño del sw a desarrollar
B22: Identificar las etapas a realizar en el proyecto, sin olvidar cada tarea en base a los WBS estándar
B23: Repartir por perfiles que ejecutarán el proyecto
B24: Pedir varias opiniones, revisar, contrastar.
B26: Pestaña Elementos Base
B27: De momento tenemos pocas tablas de estimación, pero deben ir construyéndose. CorporateQS.quality.es@inetum.world centraliza estas tablas. Todo input es bienvenido.
B28: Se debe pensar siempre en tablas reutilizables entre proyectos. Aplicar ese criterio para identificar tipologías.
... B54: Esta pestaña ayuda a recordar algunas técnicas de estimación como identificar bien las asunciones (hipótesis), evaluar al final los riesgos, comparar con otros proyectos similares, etc.
